~/workspace$ python -m cleanme.py
Traceback (most recent call last):
  File "/nix/store/qlb1pg370bb647nj4dhc81y2jszvciz7-python3-3.10.16/lib/python3.10/runpy.py", line 187, in _run_module_as_main
    mod_name, mod_spec, code = _get_module_details(mod_name, _Error)
  File "/nix/store/qlb1pg370bb647nj4dhc81y2jszvciz7-python3-3.10.16/lib/python3.10/runpy.py", line 110, in _get_module_details
    __import__(pkg_name)
  File "/home/runner/workspace/cleanme.py", line 3, in <module>
    import pandas as pd
  File "/home/runner/workspace/.pythonlibs/lib/python3.10/site-packages/pandas/__init__.py", line 22, in <module>
    from pandas.compat import is_numpy_dev as _is_numpy_dev  # pyright: ignore # noqa:F401
  File "/home/runner/workspace/.pythonlibs/lib/python3.10/site-packages/pandas/compat/__init__.py", line 18, in <module>
    from pandas.compat.numpy import (
  File "/home/runner/workspace/.pythonlibs/lib/python3.10/site-packages/pandas/compat/numpy/__init__.py", line 4, in <module>
    from pandas.util.version import Version
  File "/home/runner/workspace/.pythonlibs/lib/python3.10/site-packages/pandas/util/__init__.py", line 2, in <module>
    from pandas.util._decorators import (  # noqa:F401
  File "/home/runner/workspace/.pythonlibs/lib/python3.10/site-packages/pandas/util/_decorators.py", line 14, in <module>
    from pandas._libs.properties import cache_readonly
  File "/home/runner/workspace/.pythonlibs/lib/python3.10/site-packages/pandas/_libs/__init__.py", line 13, in <module>
    from pandas._libs.interval import Interval
  File "pandas/_libs/interval.pyx", line 1, in init pandas._libs.interval
ValueError: numpy.dtype size changed, may indicate binary incompatibility. Expected 96 from C header, got 88 from PyObject
~/workspace$ python  cleanme.py
Traceback (most recent call last):
  File "/home/runner/workspace/cleanme.py", line 3, in <module>
    import pandas as pd
  File "/home/runner/workspace/.pythonlibs/lib/python3.10/site-packages/pandas/__init__.py", line 22, in <module>
    from pandas.compat import is_numpy_dev as _is_numpy_dev  # pyright: ignore # noqa:F401
  File "/home/runner/workspace/.pythonlibs/lib/python3.10/site-packages/pandas/compat/__init__.py", line 18, in <module>
    from pandas.compat.numpy import (
  File "/home/runner/workspace/.pythonlibs/lib/python3.10/site-packages/pandas/compat/numpy/__init__.py", line 4, in <module>
    from pandas.util.version import Version
  File "/home/runner/workspace/.pythonlibs/lib/python3.10/site-packages/pandas/util/__init__.py", line 2, in <module>
    from pandas.util._decorators import (  # noqa:F401
  File "/home/runner/workspace/.pythonlibs/lib/python3.10/site-packages/pandas/util/_decorators.py", line 14, in <module>
    from pandas._libs.properties import cache_readonly
  File "/home/runner/workspace/.pythonlibs/lib/python3.10/site-packages/pandas/_libs/__init__.py", line 13, in <module>
    from pandas._libs.interval import Interval
  File "pandas/_libs/interval.pyx", line 1, in init pandas._libs.interval
ValueError: numpy.dtype size changed, may indicate binary incompatibility. Expected 96 from C header, got 88 from PyObject